<sdf version='1.7'>
  <world name='default'>
    <model name='ground_plane'>
      <static>1</static>
      <link name='link'>
        <collision name='collision'>
          <geometry>
            <plane>
              <normal>0 0 1</normal>
              <size>100 100</size>
            </plane>
          </geometry>
          <surface>
            <contact>
              <collide_bitmask>65535</collide_bitmask>
              <ode/>
            </contact>
            <friction>
              <ode>
                <mu>100</mu>
                <mu2>50</mu2>
              </ode>
              <torsional>
                <ode/>
              </torsional>
            </friction>
            <bounce/>
          </surface>
          <max_contacts>10</max_contacts>
        </collision>
        <visual name='visual'>
          <cast_shadows>0</cast_shadows>
          <geometry>
            <plane>
              <normal>0 0 1</normal>
              <size>100 100</size>
            </plane>
          </geometry>
          <material>
            <script>
              <uri>file://media/materials/scripts/gazebo.material</uri>
              <name>Gazebo/Grey</name>
            </script>
          </material>
        </visual>
        <self_collide>0</self_collide>
        <enable_wind>0</enable_wind>
        <kinematic>0</kinematic>
      </link>
    </model>
    <light name='sun' type='directional'>
      <cast_shadows>1</cast_shadows>
      <pose>0 0 10 0 -0 0</pose>
      <diffuse>0.8 0.8 0.8 1</diffuse>
      <specular>0.2 0.2 0.2 1</specular>
      <attenuation>
        <range>1000</range>
        <constant>0.9</constant>
        <linear>0.01</linear>
        <quadratic>0.001</quadratic>
      </attenuation>
      <direction>-0.5 0.1 -0.9</direction>
      <spot>
        <inner_angle>0</inner_angle>
        <outer_angle>0</outer_angle>
        <falloff>0</falloff>
      </spot>
    </light>
    <model name='all_build'>
      <pose>0 0 0 0 -0 0</pose>
      <static>1</static>
      <link name='body'>
        <collision name='environment_model_collision'>
          <geometry>
            <mesh>
              <uri>model://one_hard_build.dae</uri>
            </mesh>
          </geometry>
          <max_contacts>10</max_contacts>
          <surface>
            <contact>
              <ode/>
            </contact>
            <bounce/>
            <friction>
              <torsional>
                <ode/>
              </torsional>
              <ode/>
            </friction>
          </surface>
        </collision>
        <visual name='visual'>
          <geometry>
            <mesh>
              <uri>model://one_hard_build.dae</uri>
            </mesh>
          </geometry>
        </visual>
        <self_collide>0</self_collide>
        <enable_wind>0</enable_wind>
        <kinematic>0</kinematic>
      </link>
    </model>
    <gravity>0 0 -9.8</gravity>
    <magnetic_field>6e-06 2.3e-05 -4.2e-05</magnetic_field>
    <atmosphere type='adiabatic'/>
    <physics type='ode'>
      <max_step_size>0.001</max_step_size>
      <real_time_factor>1</real_time_factor>
      <real_time_update_rate>1000</real_time_update_rate>
    </physics>
    <scene>
      <ambient>0.4 0.4 0.4 1</ambient>
      <background>0.7 0.7 0.7 1</background>
      <shadows>1</shadows>
    </scene>
    <wind/>
    <spherical_coordinates>
      <surface_model>EARTH_WGS84</surface_model>
      <latitude_deg>0</latitude_deg>
      <longitude_deg>0</longitude_deg>
      <elevation>0</elevation>
      <heading_deg>0</heading_deg>
    </spherical_coordinates>
    <state world_name='default'>
      <sim_time>605 28000000</sim_time>
      <real_time>223 899960254</real_time>
      <wall_time>1655827931 660857748</wall_time>
      <iterations>221848</iterations>
      <model name='all_build'>
        <pose>0 0 -0.960532 0 -0 0</pose>
        <scale>1 1 1</scale>
        <link name='body'>
          <pose>0 0 -0.960532 0 -0 0</pose>
          <velocity>0 0 0 0 -0 0</velocity>
          <acceleration>0 0 0 0 -0 0</acceleration>
          <wrench>0 0 0 0 -0 0</wrench>
        </link>
      </model>
      <model name='asphalt_ground_plane'>
        <pose>8.26398 8.0628 0 0 -0 1.5708</pose>
        <scale>1 0.964705 1</scale>
        <link name='link'>
          <pose>8.26398 8.0628 0 0 -0 1.5708</pose>
          <velocity>0 0 0 0 -0 0</velocity>
          <acceleration>0 0 0 0 -0 0</acceleration>
          <wrench>0 0 0 0 -0 0</wrench>
        </link>
      </model>
      <model name='ground_plane'>
        <pose>0 0 0 0 -0 0</pose>
        <scale>1 1 1</scale>
        <link name='link'>
          <pose>0 0 0 0 -0 0</pose>
          <velocity>0 0 0 0 -0 0</velocity>
          <acceleration>0 0 0 0 -0 0</acceleration>
          <wrench>0 0 0 0 -0 0</wrench>
        </link>
      </model>
      <model name='robot'>
        <pose>0.264394 0.014572 0.049861 -1e-06 0.000279 0.020527</pose>
        <scale>1 1 1</scale>
        <link name='base_footprint'>
          <pose>0.264394 0.014572 0.049861 -1e-06 0.000279 0.020527</pose>
          <velocity>0.000199 4.5e-05 -0.000735 -2.3e-05 0.001523 7.2e-05</velocity>
          <acceleration>-0.022919 -0.001796 0.510075 -0.010244 -0.834631 0.011976</acceleration>
          <wrench>-7.79249 -0.610531 173.426 0 -0 0</wrench>
        </link>
        <link name='steer_front_left_wheel'>
          <pose>0.756143 0.424752 0.300117 -2e-06 0.000279 0.020515</pose>
          <velocity>0.00084 8.9e-05 0.014883 -0.000425 0.00151 -3e-06</velocity>
          <acceleration>-0.168671 0.005236 65.5183 -0.847628 -0.871851 -0.149027</acceleration>
          <wrench>-0.016867 0.000524 6.55183 0 -0 0</wrench>
        </link>
        <link name='steer_front_right_wheel'>
          <pose>0.772563 -0.375079 0.300117 -1e-06 0.000279 0.020515</pose>
          <velocity>0.0009 8.8e-05 0.014886 -0.000421 0.00152 -3e-06</velocity>
          <acceleration>-0.168502 -0.044654 65.5472 -0.639791 -0.828735 -0.148791</acceleration>
          <wrench>-0.01685 -0.004465 6.55472 0 -0 0</wrench>
        </link>
        <link name='wheel_front_left_wheel'>
          <pose>0.756144 0.424752 0.3 -5e-06 1.2831 0.020511</pose>
          <velocity>0.000752 8.5e-05 0.010143 -0.000339 0.003008 8e-06</velocity>
          <acceleration>-0.045634 -0.004154 46.6982 -0.607449 -0.016659 -0.132297</acceleration>
          <wrench>-0.912671 -0.083087 933.965 0 -0 0</wrench>
        </link>
        <link name='wheel_front_right_wheel'>
          <pose>0.772564 -0.375079 0.3 -5e-06 1.32853 0.02051</pose>
          <velocity>0.00081 8.8e-05 0.010143 -0.000352 0.003239 8e-06</velocity>
          <acceleration>-0.047149 -0.026668 46.713 -0.499348 -0.013653 -0.132233</acceleration>
          <wrench>-0.942989 -0.533353 934.26 0 -0 0</wrench>
        </link>
        <link name='wheel_rear_left_wheel'>
          <pose>-0.243642 0.404227 0.3 -6e-06 0.805304 0.020523</pose>
          <velocity>0.00054 1.3e-05 1.8e-05 -5.1e-05 0.002125 9.6e-05</velocity>
          <acceleration>0.253233 0.005938 0.091075 0.012479 -0.232292 0.035069</acceleration>
          <wrench>5.06467 0.118766 1.8215 0 -0 0</wrench>
        </link>
        <link name='wheel_rear_right_wheel'>
          <pose>-0.227221 -0.395605 0.300001 5e-06 0.892382 0.020529</pose>
          <velocity>0.000594 9e-06 1e-05 -4.1e-05 0.002376 1.7e-05</velocity>
          <acceleration>0.258847 0.001122 0.068787 0.024581 0.018697 -0.043782</acceleration>
          <wrench>5.17694 0.022445 1.37574 0 -0 0</wrench>
        </link>
      </model>
      <light name='sun'>
        <pose>0 0 10 0 -0 0</pose>
      </light>
    </state>
    <gui fullscreen='0'>
      <camera name='user_camera'>
        <pose>-20.6295 -10.6048 92.0433 0 1.2058 -0.012565</pose>
        <view_controller>orbit</view_controller>
        <projection_type>perspective</projection_type>
      </camera>
    </gui>
    <model name='robot'>
      <link name='base_footprint'>
        <inertial>
          <pose>0 0 0.6 0 -0 0</pose>
          <mass>340</mass>
          <inertia>
            <ixx>26.1375</ixx>
            <ixy>0</ixy>
            <ixz>-6.38125e-06</ixz>
            <iyy>107.171</iyy>
            <iyz>0</iyz>
            <izz>112.908</izz>
          </inertia>
        </inertial>
        <collision name='base_footprint_fixed_joint_lump__base_collision_collision'>
          <pose>0 0 0.6 0 -0 0</pose>
          <geometry>
            <box>
              <size>1.85 0.75 0.6</size>
            </box>
          </geometry>
          <max_contacts>10</max_contacts>
          <surface>
            <contact>
              <ode/>
            </contact>
            <bounce/>
            <friction>
              <torsional>
                <ode/>
              </torsional>
              <ode/>
            </friction>
          </surface>
        </collision>
        <collision name='base_footprint_fixed_joint_lump__gps_link_collision_1'>
          <pose>0 0 0.925 0 -0 0</pose>
          <geometry>
            <box>
              <size>0.2 0.2 0.05</size>
            </box>
          </geometry>
          <surface>
            <contact>
              <ode/>
            </contact>
            <friction>
              <ode/>
              <torsional>
                <ode/>
              </torsional>
            </friction>
            <bounce/>
          </surface>
          <max_contacts>10</max_contacts>
        </collision>
        <collision name='base_footprint_fixed_joint_lump__imu_link_collision_2'>
          <pose>0.825 0 0.925 0 -0 0</pose>
          <geometry>
            <box>
              <size>0.2 0.2 0.05</size>
            </box>
          </geometry>
          <surface>
            <contact>
              <ode/>
            </contact>
            <friction>
              <ode/>
              <torsional>
                <ode/>
              </torsional>
            </friction>
            <bounce/>
          </surface>
          <max_contacts>10</max_contacts>
        </collision>
        <collision name='base_footprint_fixed_joint_lump__rs_camera_link_collision_3'>
          <pose>0.925 0 1 0 -0 0</pose>
          <geometry>
            <box>
              <size>0.02 0.2 0.02</size>
            </box>
          </geometry>
          <surface>
            <contact>
              <ode/>
            </contact>
            <friction>
              <ode/>
              <torsional>
                <ode/>
              </torsional>
            </friction>
            <bounce/>
          </surface>
          <max_contacts>10</max_contacts>
        </collision>
        <visual name='base_footprint_fixed_joint_lump__base_link_visual'>
          <pose>0 0 0.6 0 -0 0</pose>
          <geometry>
            <box>
              <size>1.85 0.75 0.6</size>
            </box>
          </geometry>
        </visual>
        <visual name='base_footprint_fixed_joint_lump__gps_link_visual_1'>
          <pose>0 0 0.925 0 -0 0</pose>
          <geometry>
            <box>
              <size>0.2 0.2 0.05</size>
            </box>
          </geometry>
          <material>
            <script>
              <name>Gazebo/Orange</name>
              <uri>file://media/materials/scripts/gazebo.material</uri>
            </script>
          </material>
        </visual>
        <visual name='base_footprint_fixed_joint_lump__imu_link_visual_2'>
          <pose>0.825 0 0.925 0 -0 0</pose>
          <geometry>
            <box>
              <size>0.2 0.2 0.05</size>
            </box>
          </geometry>
          <material>
            <script>
              <name>Gazebo/Red</name>
              <uri>file://media/materials/scripts/gazebo.material</uri>
            </script>
          </material>
        </visual>
        <visual name='base_footprint_fixed_joint_lump__rs_camera_link_visual_3'>
          <pose>0.925 0 1 0 -0 0</pose>
          <geometry>
            <box>
              <size>0.02 0.2 0.02</size>
            </box>
          </geometry>
          <material>
            <script>
              <name>Gazebo/Black</name>
              <uri>file://media/materials/scripts/gazebo.material</uri>
            </script>
          </material>
        </visual>
        <gravity>1</gravity>
        <sensor name='imu_sensor' type='imu'>
          <always_on>1</always_on>
          <update_rate>100</update_rate>
          <visualize>1</visualize>
          <topic>__default_topic__</topic>
          <plugin name='imu_plugin' filename='libgazebo_ros_imu_sensor.so'>
            <topicName>tigra/imu</topicName>
            <bodyName>imu_link</bodyName>
            <updateRateHZ>20.0</updateRateHZ>
            <gaussianNoise>0.0</gaussianNoise>
            <xyzOffset>0 0 0</xyzOffset>
            <rpyOffset>0 0 0</rpyOffset>
            <frameName>imu_link</frameName>
            <robotNamespace>/</robotNamespace>
          </plugin>
          <pose>0.825 0 0.925 0 -0 0</pose>
          <imu/>
        </sensor>
        <sensor name='rs_camera_link_camera' type='depth'>
          <update_rate>20</update_rate>
          <camera>
            <horizontal_fov>1.39626</horizontal_fov>
            <image>
              <width>640</width>
              <height>480</height>
              <format>R8G8B8</format>
            </image>
            <clip>
              <near>0.05</near>
              <far>300</far>
            </clip>
          </camera>
          <plugin name='camera_plugin' filename='libgazebo_ros_openni_kinect.so'>
            <baseline>0.2</baseline>
            <alwaysOn>1</alwaysOn>
            <updateRate>20.0</updateRate>
            <cameraName>rs_camera</cameraName>
            <imageTopicName>/rs_camera/color/image_raw</imageTopicName>
            <cameraInfoTopicName>/rs_camera/color/camera_info</cameraInfoTopicName>
            <depthImageTopicName>/rs_camera/depth/image_raw</depthImageTopicName>
            <depthImageCameraInfoTopicName>/rs_camera/depth/camera_info</depthImageCameraInfoTopicName>
            <pointCloudTopicName>/rs_camera/depth/color/points</pointCloudTopicName>
            <frameName>rs_camera_optical_frame</frameName>
            <pointCloudCutoff>0.05</pointCloudCutoff>
            <pointCloudCutoffMax>15</pointCloudCutoffMax>
            <distortionK1>0</distortionK1>
            <distortionK2>0</distortionK2>
            <distortionK3>0</distortionK3>
            <distortionT1>0</distortionT1>
            <distortionT2>0</distortionT2>
            <CxPrime>0</CxPrime>
            <Cx>0</Cx>
            <Cy>0</Cy>
            <focalLength>0</focalLength>
            <hackBaseline>0</hackBaseline>
            <robotNamespace>/</robotNamespace>
          </plugin>
          <pose>0.925 0 1 0 -0 0</pose>
        </sensor>
        <self_collide>0</self_collide>
        <enable_wind>0</enable_wind>
        <kinematic>0</kinematic>
      </link>
      <joint name='front_left_wheel_steer_joint' type='revolute'>
        <pose relative_to='base_footprint'>0.5 0.4 0.25 0 -0 0</pose>
        <parent>base_footprint</parent>
        <child>steer_front_left_wheel</child>
        <axis>
          <xyz>0 0 1</xyz>
          <limit>
            <lower>-0.785398</lower>
            <upper>0.785398</upper>
            <effort>1000</effort>
            <velocity>0</velocity>
          </limit>
          <dynamics>
            <spring_reference>0</spring_reference>
            <spring_stiffness>0</spring_stiffness>
          </dynamics>
        </axis>
      </joint>
      <link name='steer_front_left_wheel'>
        <pose relative_to='front_left_wheel_steer_joint'>0 0 0 0 -0 0</pose>
        <inertial>
          <pose>0 0 0 0 -0 0</pose>
          <mass>0.1</mass>
          <inertia>
            <ixx>0.01</ixx>
            <ixy>0</ixy>
            <ixz>0</ixz>
            <iyy>0.01</iyy>
            <iyz>0</iyz>
            <izz>0.01</izz>
          </inertia>
        </inertial>
        <self_collide>0</self_collide>
        <enable_wind>0</enable_wind>
        <kinematic>0</kinematic>
      </link>
      <joint name='front_left_wheel_speed_joint' type='revolute'>
        <pose relative_to='steer_front_left_wheel'>0 0 0 0 -0 0</pose>
        <parent>steer_front_left_wheel</parent>
        <child>wheel_front_left_wheel</child>
        <axis>
          <xyz>0 1 0</xyz>
          <limit>
            <effort>500</effort>
            <velocity>10</velocity>
            <lower>-1e+16</lower>
            <upper>1e+16</upper>
          </limit>
          <dynamics>
            <spring_reference>0</spring_reference>
            <spring_stiffness>0</spring_stiffness>
          </dynamics>
        </axis>
      </joint>
      <link name='wheel_front_left_wheel'>
        <pose relative_to='front_left_wheel_speed_joint'>0 0 0 0 -0 0</pose>
        <inertial>
          <pose>0 0 0 1.5708 -0 0</pose>
          <mass>20</mass>
          <inertia>
            <ixx>0.416667</ixx>
            <ixy>0</ixy>
            <ixz>0</ixz>
            <iyy>0.416667</iyy>
            <iyz>0</iyz>
            <izz>0.625</izz>
          </inertia>
        </inertial>
        <collision name='wheel_front_left_wheel_collision'>
          <pose>0 0 0 1.5708 -0 0</pose>
          <geometry>
            <cylinder>
              <length>0.25</length>
              <radius>0.25</radius>
            </cylinder>
          </geometry>
          <max_contacts>10</max_contacts>
          <surface>
            <contact>
              <ode/>
            </contact>
            <bounce/>
            <friction>
              <torsional>
                <ode/>
              </torsional>
              <ode/>
            </friction>
          </surface>
        </collision>
        <visual name='wheel_front_left_wheel_visual'>
          <pose>0 0 0 1.5708 -0 0</pose>
          <geometry>
            <cylinder>
              <length>0.25</length>
              <radius>0.25</radius>
            </cylinder>
          </geometry>
        </visual>
        <self_collide>0</self_collide>
        <enable_wind>0</enable_wind>
        <kinematic>0</kinematic>
      </link>
      <joint name='front_right_wheel_steer_joint' type='revolute'>
        <pose relative_to='base_footprint'>0.5 -0.4 0.25 0 -0 0</pose>
        <parent>base_footprint</parent>
        <child>steer_front_right_wheel</child>
        <axis>
          <xyz>0 0 1</xyz>
          <limit>
            <lower>-0.785398</lower>
            <upper>0.785398</upper>
            <effort>1000</effort>
            <velocity>0</velocity>
          </limit>
          <dynamics>
            <spring_reference>0</spring_reference>
            <spring_stiffness>0</spring_stiffness>
          </dynamics>
        </axis>
      </joint>
      <link name='steer_front_right_wheel'>
        <pose relative_to='front_right_wheel_steer_joint'>0 0 0 0 -0 0</pose>
        <inertial>
          <pose>0 0 0 0 -0 0</pose>
          <mass>0.1</mass>
          <inertia>
            <ixx>0.01</ixx>
            <ixy>0</ixy>
            <ixz>0</ixz>
            <iyy>0.01</iyy>
            <iyz>0</iyz>
            <izz>0.01</izz>
          </inertia>
        </inertial>
        <self_collide>0</self_collide>
        <enable_wind>0</enable_wind>
        <kinematic>0</kinematic>
      </link>
      <joint name='front_right_wheel_speed_joint' type='revolute'>
        <pose relative_to='steer_front_right_wheel'>0 0 0 0 -0 0</pose>
        <parent>steer_front_right_wheel</parent>
        <child>wheel_front_right_wheel</child>
        <axis>
          <xyz>0 1 0</xyz>
          <limit>
            <effort>500</effort>
            <velocity>10</velocity>
            <lower>-1e+16</lower>
            <upper>1e+16</upper>
          </limit>
          <dynamics>
            <spring_reference>0</spring_reference>
            <spring_stiffness>0</spring_stiffness>
          </dynamics>
        </axis>
      </joint>
      <link name='wheel_front_right_wheel'>
        <pose relative_to='front_right_wheel_speed_joint'>0 0 0 0 -0 0</pose>
        <inertial>
          <pose>0 0 0 1.5708 -0 0</pose>
          <mass>20</mass>
          <inertia>
            <ixx>0.416667</ixx>
            <ixy>0</ixy>
            <ixz>0</ixz>
            <iyy>0.416667</iyy>
            <iyz>0</iyz>
            <izz>0.625</izz>
          </inertia>
        </inertial>
        <collision name='wheel_front_right_wheel_collision'>
          <pose>0 0 0 1.5708 -0 0</pose>
          <geometry>
            <cylinder>
              <length>0.25</length>
              <radius>0.25</radius>
            </cylinder>
          </geometry>
          <max_contacts>10</max_contacts>
          <surface>
            <contact>
              <ode/>
            </contact>
            <bounce/>
            <friction>
              <torsional>
                <ode/>
              </torsional>
              <ode/>
            </friction>
          </surface>
        </collision>
        <visual name='wheel_front_right_wheel_visual'>
          <pose>0 0 0 1.5708 -0 0</pose>
          <geometry>
            <cylinder>
              <length>0.25</length>
              <radius>0.25</radius>
            </cylinder>
          </geometry>
        </visual>
        <self_collide>0</self_collide>
        <enable_wind>0</enable_wind>
        <kinematic>0</kinematic>
      </link>
      <joint name='rear_left_wheel_speed_joint' type='revolute'>
        <pose relative_to='base_footprint'>-0.5 0.4 0.25 0 -0 0</pose>
        <parent>base_footprint</parent>
        <child>wheel_rear_left_wheel</child>
        <axis>
          <xyz>0 1 0</xyz>
          <limit>
            <effort>500</effort>
            <velocity>10</velocity>
            <lower>-1e+16</lower>
            <upper>1e+16</upper>
          </limit>
          <dynamics>
            <spring_reference>0</spring_reference>
            <spring_stiffness>0</spring_stiffness>
          </dynamics>
        </axis>
      </joint>
      <link name='wheel_rear_left_wheel'>
        <pose relative_to='rear_left_wheel_speed_joint'>0 0 0 0 -0 0</pose>
        <inertial>
          <pose>0 0 0 1.5708 -0 0</pose>
          <mass>20</mass>
          <inertia>
            <ixx>0.416667</ixx>
            <ixy>0</ixy>
            <ixz>0</ixz>
            <iyy>0.416667</iyy>
            <iyz>0</iyz>
            <izz>0.625</izz>
          </inertia>
        </inertial>
        <collision name='wheel_rear_left_wheel_collision'>
          <pose>0 0 0 1.5708 -0 0</pose>
          <geometry>
            <cylinder>
              <length>0.25</length>
              <radius>0.25</radius>
            </cylinder>
          </geometry>
          <max_contacts>10</max_contacts>
          <surface>
            <contact>
              <ode/>
            </contact>
            <bounce/>
            <friction>
              <torsional>
                <ode/>
              </torsional>
              <ode/>
            </friction>
          </surface>
        </collision>
        <visual name='wheel_rear_left_wheel_visual'>
          <pose>0 0 0 1.5708 -0 0</pose>
          <geometry>
            <cylinder>
              <length>0.25</length>
              <radius>0.25</radius>
            </cylinder>
          </geometry>
        </visual>
        <self_collide>0</self_collide>
        <enable_wind>0</enable_wind>
        <kinematic>0</kinematic>
      </link>
      <joint name='rear_right_wheel_speed_joint' type='revolute'>
        <pose relative_to='base_footprint'>-0.5 -0.4 0.25 0 -0 0</pose>
        <parent>base_footprint</parent>
        <child>wheel_rear_right_wheel</child>
        <axis>
          <xyz>0 1 0</xyz>
          <limit>
            <effort>500</effort>
            <velocity>10</velocity>
            <lower>-1e+16</lower>
            <upper>1e+16</upper>
          </limit>
          <dynamics>
            <spring_reference>0</spring_reference>
            <spring_stiffness>0</spring_stiffness>
          </dynamics>
        </axis>
      </joint>
      <link name='wheel_rear_right_wheel'>
        <pose relative_to='rear_right_wheel_speed_joint'>0 0 0 0 -0 0</pose>
        <inertial>
          <pose>0 0 0 1.5708 -0 0</pose>
          <mass>20</mass>
          <inertia>
            <ixx>0.416667</ixx>
            <ixy>0</ixy>
            <ixz>0</ixz>
            <iyy>0.416667</iyy>
            <iyz>0</iyz>
            <izz>0.625</izz>
          </inertia>
        </inertial>
        <collision name='wheel_rear_right_wheel_collision'>
          <pose>0 0 0 1.5708 -0 0</pose>
          <geometry>
            <cylinder>
              <length>0.25</length>
              <radius>0.25</radius>
            </cylinder>
          </geometry>
          <max_contacts>10</max_contacts>
          <surface>
            <contact>
              <ode/>
            </contact>
            <bounce/>
            <friction>
              <torsional>
                <ode/>
              </torsional>
              <ode/>
            </friction>
          </surface>
        </collision>
        <visual name='wheel_rear_right_wheel_visual'>
          <pose>0 0 0 1.5708 -0 0</pose>
          <geometry>
            <cylinder>
              <length>0.25</length>
              <radius>0.25</radius>
            </cylinder>
          </geometry>
        </visual>
        <self_collide>0</self_collide>
        <enable_wind>0</enable_wind>
        <kinematic>0</kinematic>
      </link>
      <plugin name='tigra_interface_plugin' filename='libackermann_raw_controller_plugin.so'>
        <wheelbase>1.0</wheelbase>
        <trackWidth>0.8</trackWidth>
        <robotName>tigra</robotName>
        <robotNamespace>/</robotNamespace>
      </plugin>
      <static>0</static>
      <plugin name='gazebo_ros_gps' filename='libhector_gazebo_ros_gps.so'>
        <updateRate>4.0</updateRate>
        <frameId>gps_link</frameId>
        <topicName>/gps/fix</topicName>
        <velocityTopicName>/gps/fix_velocity</velocityTopicName>
        <referenceLatitude>-30.06022459407145675</referenceLatitude>
        <referenceLongitude>-51.173913575780311191</referenceLongitude>
        <referenceHeading>90</referenceHeading>
        <referenceAltitude>10</referenceAltitude>
        <offset>0 0 0</offset>
        <drift>0.001 0.001 0.001</drift>
        <gaussianNoise>0.05 0.05 0.05</gaussianNoise>
        <velocityDrift>0.001 0.001 0.001</velocityDrift>
        <velocityGaussianNoise>0.5 0.5 0.5</velocityGaussianNoise>
        <robotNamespace>/</robotNamespace>
        <bodyName>base_footprint</bodyName>
        <xyzOffset>0 0 -0.925</xyzOffset>
        <rpyOffset>0 -0 0</rpyOffset>
      </plugin>
      <plugin name='p3d_base_controller' filename='libgazebo_ros_p3d.so'>
        <alwaysOn>1</alwaysOn>
        <updateRate>50.0</updateRate>
        <topicName>ground_truth/state</topicName>
        <gaussianNoise>0.01</gaussianNoise>
        <frameName>world</frameName>
        <xyzOffsets>0 0 0</xyzOffsets>
        <rpyOffsets>0 0 0</rpyOffsets>
        <robotNamespace>/</robotNamespace>
        <bodyName>base_footprint</bodyName>
        <xyzOffset>0 0 -0.6</xyzOffset>
        <rpyOffset>0 -0 0</rpyOffset>
      </plugin>
      <pose>0 0 0.6 0 -0 0</pose>
    </model>
    <model name='asphalt_ground_plane'>
      <static>1</static>
      <link name='link'>
        <collision name='collision'>
          <geometry>
            <box>
              <size>55 90 0.1</size>
            </box>
          </geometry>
          <surface>
            <friction>
              <ode>
                <mu>100</mu>
                <mu2>50</mu2>
              </ode>
              <torsional>
                <ode/>
              </torsional>
            </friction>
            <contact>
              <ode/>
            </contact>
            <bounce/>
          </surface>
          <max_contacts>10</max_contacts>
        </collision>
        <visual name='visual'>
          <cast_shadows>0</cast_shadows>
          <geometry>
            <box>
              <size>55 90 0.1</size>
            </box>
          </geometry>
          <material>
            <script>
              <uri>model://asphalt_ground_plane/materials/scripts</uri>
              <uri>model://asphalt_ground_plane/materials/textures/</uri>
              <name>AsphaltGroundPlane/Image</name>
            </script>
          </material>
        </visual>
        <self_collide>0</self_collide>
        <enable_wind>0</enable_wind>
        <kinematic>0</kinematic>
      </link>
      <pose>6.66104 4.31513 0 0 -0 0</pose>
    </model>
  </world>
</sdf>
