<?xml version="1.0"?>
<robot xmlns:xacro="http://www.ros.org/wiki/xacro">

	<xacro:property name="wheel_width" value="0.25" />
	<xacro:property name="wheel_radius" value="0.25" />
	<xacro:property name="wheel_mass" value="20" />
	<xacro:property name="wheel_turn_limit" value="${pi/4}" />
	<xacro:property name="mid_wheel_turn_limit" value="${degrees_30}" />

	<xacro:include filename="$(find tigra_description)/urdf/macros/inertia.urdf.xacro" />
	<xacro:include filename="$(find tigra_description)/urdf/macros/common.urdf.xacro" />

	<!-- XACRO WHEEL -->
	<xacro:macro name="base_wheel" params="name">
		<link name="${name}">
			<visual>
				<origin xyz="0 0 0" rpy="${pi/2} 0 0" />
				<geometry>
					<cylinder length="${wheel_width}" radius="${wheel_radius}" />
				</geometry>
			</visual>
			<collision>
				<origin xyz="0 0 0" rpy="${pi/2} 0 0" />
				<geometry>
					<cylinder length="${wheel_width}" radius="${wheel_radius}" />
				</geometry>
			</collision>
			<cylinder_inertia r="${wheel_radius}" h="${wheel_width}" mass="${wheel_mass}">
				<origin xyz="0 0 0" rpy="${pi/2} 0 0" />
			</cylinder_inertia>
		</link>
	</xacro:macro>

	<!-- XACRO SPEED -->
	<xacro:macro name="speed_wheel" params="name base_name xyz ">
		<base_wheel name="wheel_${name}" />
		<joint name="${name}_speed_joint" type="continuous">
			<parent link="${base_name}" />
			<child link="wheel_${name}" />
			<origin xyz="${xyz}" rpy="0 0 0" />
			<axis xyz="0 1 0" />
			<limit effort="500.0" velocity="10.0" />
		</joint>
	</xacro:macro>

	<!-- XACRO STEER -->
	<xacro:macro name="steer_wheel" params="name base_name xyz">
		<base_wheel name="wheel_${name}" />
		<joint name="${name}_steer_joint" type="revolute">
			<limit lower="${-wheel_turn_limit}" upper="${wheel_turn_limit}" effort="1000" velocity="0" />
			<parent link="${base_name}" />
			<child link="steer_${name}" />
			<origin xyz="${xyz}" rpy="0 0 0" />
			<axis xyz="0 0 1" />
		</joint>

		<link name="steer_${name}">
			<null_inertial />
		</link>

		<joint name="${name}_speed_joint" type="continuous">
			<parent link="steer_${name}" />
			<child link="wheel_${name}" />
			<origin xyz="0 0 0" rpy="0 0 0" />
			<axis xyz="0 1 0" />
			<limit effort="500" velocity="10.0" />
		</joint>
	</xacro:macro>
</robot>